Workbook

Sheet CBM Log Sheet
D1: CBM DASHBOARD FILE
A6: FPSO | B6: Tag | C6: Asset_TAG | D6: Machine Description | E6: Date | F6: Status | G6: Measurement Type | H6: Comments | I6: WO Number
A7: DNY | B7: 111-PKPD-0100 | C7: =IFERROR(VLOOKUP(A7&"_"&B7,'CBM Assets List'!A:A,1,0),0) -> DNY_111-PKPD-0100 | D7: Emergency Diesel Generator | E7: 45962 | F7: Unmeasured
A8: DNY | B8: 111-PKPD-0200 | C8: =IFERROR(VLOOKUP(A8&"_"&B8,'CBM Assets List'!A:A,1,0),0) -> DNY_111-PKPD-0200 | D8: Essential Generator No1 | E8: 45962 | F8: Unmeasured
A9: DNY | B9: 111-PKPD-0300 | C9: =IFERROR(VLOOKUP(A9&"_"&B9,'CBM Assets List'!A:A,1,0),0) -> DNY_111-PKPD-0300 | D9: Essential Generator No2 | E9: 45962 | F9: Unmeasured
A10: DNY | B10: 111-PKPD-0400 | C10: =IFERROR(VLOOKUP(A10&"_"&B10,'CBM Assets List'!A:A,1,0),0) -> DNY_111-PKPD-0400 | D10: Essential Generator No3 | E10: 45962 | F10: Unmeasured
A11: DNY | B11: 112-DRST-9502 | C11: =IFERROR(VLOOKUP(A11&"_"&B11,'CBM Assets List'!A:A,1,0),0) -> 0 | D11: Ballast Pump - Steam Turbine | E11: 45962 | F11: Unmeasured
A12: DNY | B12: 112-PUBA-9001 | C12: =IFERROR(VLOOKUP(A12&"_"&B12,'CBM Assets List'!A:A,1,0),0) -> 0 | D12: Ballast Pump - Steam Turbine | E12: 45962 | F12: Unmeasured
A13: DNY | B13: 115-HVSF-9001-A | C13: =IFERROR(VLOOKUP(A13&"_"&B13,'CBM Assets List'!A:A,1,0),0) -> DNY_115-HVSF-9001-A | D13: FD Fan A | E13: 45962 | F13: Unmeasured
A14: DNY | B14: 115-HVSF-9001-B | C14: =IFERROR(VLOOKUP(A14&"_"&B14,'CBM Assets List'!A:A,1,0),0) -> DNY_115-HVSF-9001-B | D14: FD Fan B | E14: 45962 | F14: Unmeasured
A15: DNY | B15: 115-PUCE-9501-A | C15: =IFERROR(VLOOKUP(A15&"_"&B15,'CBM Assets List'!A:A,1,0),0) -> DNY_115-PUCE-9501-A | D15: Boiler Main Feed Water Pump A | E15: 45962 | F15: Unmeasured
A16: DNY | B16: 115-PUCE-9503-B | C16: =IFERROR(VLOOKUP(A16&"_"&B16,'CBM Assets List'!A:A,1,0),0) -> DNY_115-PUCE-9503-B | D16: COPT Condensate Pump B | E16: 45962 | F16: Unmeasured
A17: DNY | B17: 116-PUCE-0003-A | C17: =IFERROR(VLOOKUP(A17&"_"&B17,'CBM Assets List'!A:A,1,0),0) -> DNY_116-PUCE-0003-A | D17: MGO (GT) Service Pump A | E17: 45962 | F17: Unmeasured
A18: DNY | B18: 116-PUCE-0003-B | C18: =IFERROR(VLOOKUP(A18&"_"&B18,'CBM Assets List'!A:A,1,0),0) -> DNY_116-PUCE-0003-B | D18: MGO (GT) Service Pump B | E18: 45962 | F18: Unmeasured
... A208: PTY | B208: 772-PURE-0103-B | C208: =IFERROR(VLOOKUP(A208&"_"&B208,'CBM Assets List'!A:A,1,0),0) -> PTY_772-PURE-0103-B | D208: TEG Circulation Pump B | E208: 45962 | F208: Unmeasured
A209: DNY | B209: 111-PKPG-0100 | C209: =IFERROR(VLOOKUP(A209&"_"&B209,'CBM Assets List'!A:A,1,0),0) -> DNY_111-PKPG-0100 | D209: Main Power Generator A | E209: 45962 | G209: S1
A210: DNY | B210: 111-PKPG-0200 | C210: =IFERROR(VLOOKUP(A210&"_"&B210,'CBM Assets List'!A:A,1,0),0) -> DNY_111-PKPG-0200 | D210: Main Power Generator B | E210: 45962 | G210: S1
A211: DNY | B211: 111-PKPG-0300 | C211: =IFERROR(VLOOKUP(A211&"_"&B211,'CBM Assets List'!A:A,1,0),0) -> DNY_111-PKPG-0300 | D211: Main Power Generator C | E211: 45962 | G211: S1
A212: DNY | B212: 111-PKPG-0400 | C212: =IFERROR(VLOOKUP(A212&"_"&B212,'CBM Assets List'!A:A,1,0),0) -> DNY_111-PKPG-0400 | D212: Main Power Generator D | E212: 45962 | G212: S1
A213: DNY | B213: 115-PUCE-9501-B | C213: =IFERROR(VLOOKUP(A213&"_"&B213,'CBM Assets List'!A:A,1,0),0) -> DNY_115-PUCE-9501-B | D213: Boiler Main Feed Water Pump B | E213: 45962 | F213: Progressed Fault
A214: DNY | B214: 115-PUCE-9503-A | C214: =IFERROR(VLOOKUP(A214&"_"&B214,'CBM Assets List'!A:A,1,0),0) -> DNY_115-PUCE-9503-A | D214: COPT Condensate Pump A | E214: 45962 | F214: Progressed Fault
A215: DNY | B215: 118-COSC-0010-A | C215: =IFERROR(VLOOKUP(A215&"_"&B215,'CBM Assets List'!A:A,1,0),0) -> DNY_118-COSC-0010-A | D215: Instrument Air Compressor A | E215: 45962 | F215: Early Stage Fault
A216: DNY | B216: 118-COSC-0010-B | C216: =IFERROR(VLOOKUP(A216&"_"&B216,'CBM Assets List'!A:A,1,0),0) -> DNY_118-COSC-0010-B | D216: Instrument Air Compressor B | E216: 45962 | F216: Acceptable
A217: DNY | B217: 118-COSC-0012-A | C217: =IFERROR(VLOOKUP(A217&"_"&B217,'CBM Assets List'!A:A,1,0),0) -> DNY_118-COSC-0012-A | D217: N2 Feed Air Compressor A | E217: 45962 | F217: Acceptable
A218: DNY | B218: 118-COSC-0012-B | C218: =IFERROR(VLOOKUP(A218&"_"&B218,'CBM Assets List'!A:A,1,0),0) -> DNY_118-COSC-0012-B | D218: N2 Feed Air Compressor B | E218: 45962 | F218: Early Stage Fault
A219: DNY | B219: 120-PUCE-0010-B | C219: =IFERROR(VLOOKUP(A219&"_"&B219,'CBM Assets List'!A:A,1,0),0) -> DNY_120-PUCE-0010-B | D219: Heating Medium Pump B | E219: 45962 | F219: Early Stage Fault
A220: DNY | B220: 125-PUCE-0010-A | C220: =IFERROR(VLOOKUP(A220&"_"&B220,'CBM Assets List'!A:A,1,0),0) -> DNY_125-PUCE-0010-A | D220: Cooling Medium Pump A | E220: 45962 | F220: Acceptable
A221: DNY | B221: 125-PUCE-0010-B | C221: =IFERROR(VLOOKUP(A221&"_"&B221,'CBM Assets List'!A:A,1,0),0) -> DNY_125-PUCE-0010-B | D221: Cooling Medium Pump B | E221: 45962 | F221: Acceptable
A222: DNY | B222: 126-PUCE-0010-A | C222: =IFERROR(VLOOKUP(A222&"_"&B222,'CBM Assets List'!A:A,1,0),0) -> DNY_126-PUCE-0010-A | D222: SW Treatment HP Feed Pump A | E222: 45962 | F222: Acceptable
A223: DNY | B223: 126-PUCE-0010-B | C223: =IFERROR(VLOOKUP(A223&"_"&B223,'CBM Assets List'!A:A,1,0),0) -> DNY_126-PUCE-0010-B | D223: SW Treatment HP Feed Pump B | E223: 45962 | F223: Acceptable
A224: DNY | B224: 126-PUCE-0030-A | C224: =IFERROR(VLOOKUP(A224&"_"&B224,'CBM Assets List'!A:A,1,0),0) -> DNY_126-PUCE-0030-A | D224: Water Injection Booster Pump A | E224: 45962 | F224: Early Stage Fault
... A227: DNY | B227: 126-PUCE-0310-B | C227: =IFERROR(VLOOKUP(A227&"_"&B227,'CBM Assets List'!A:A,1,0),0) -> DNY_126-PUCE-0310-B | D227: Vacuum Pump B | E227: 45962 | F227: Early Stage Fault
A228: DNY | B228: 126-PUCE-0610 | C228: =IFERROR(VLOOKUP(A228&"_"&B228,'CBM Assets List'!A:A,1,0),0) -> DNY_126-PUCE-0610 | D228: Water Injection Pump A | E228: 45962 | G228: S1
A229: DNY | B229: 126-PUCE-0710 | C229: =IFERROR(VLOOKUP(A229&"_"&B229,'CBM Assets List'!A:A,1,0),0) -> DNY_126-PUCE-0710 | D229: Water Injection Pump B | E229: 45962 | G229: S1
A230: DNY | B230: 126-PUCE-0810 | C230: =IFERROR(VLOOKUP(A230&"_"&B230,'CBM Assets List'!A:A,1,0),0) -> DNY_126-PUCE-0810 | D230: Water Injection Pump C | E230: 45962 | G230: S1
A231: DNY | B231: 667-PUCE-0020-A | C231: =IFERROR(VLOOKUP(A231&"_"&B231,'CBM Assets List'!A:A,1,0),0) -> DNY_667-PUCE-0020-A | D231: Dead Oil Circulation Pump A | E231: 45962 | G231: S1
A232: DNY | B232: 667-PUCE-0020-B | C232: =IFERROR(VLOOKUP(A232&"_"&B232,'CBM Assets List'!A:A,1,0),0) -> DNY_667-PUCE-0020-B | D232: Dead Oil Circulation Pump B | E232: 45962 | G232: S1
A233: DNY | B233: 771-PKGC-0100 | C233: =IFERROR(VLOOKUP(A233&"_"&B233,'CBM Assets List'!A:A,1,0),0) -> DNY_771-PKGC-0100 | D233: Main Gas Compressor A | E233: 45962 | G233: S1
A234: DNY | B234: 771-PKGC-0200 | C234: =IFERROR(VLOOKUP(A234&"_"&B234,'CBM Assets List'!A:A,1,0),0) -> DNY_771-PKGC-0200 | D234: Main Gas Compressor B | E234: 45962 | G234: S1
A235: DNY | B235: 771-PKGC-0500 | C235: =IFERROR(VLOOKUP(A235&"_"&B235,'CBM Assets List'!A:A,1,0),0) -> DNY_771-PKGC-0500 | D235: LP Flash Gas Compressor | E235: 45962 | F235: Acceptable | G235: S1
...

Sheet CBM Assets List
A1: Asset_TAG | B1: Machine Description | C1: Method | D1: Frequency
A2: DNY_111-PKPD-0100 | B2: Emergency Diesel Generator | C2: Offline/Manual | D2: Quartely
A3: DNY_111-PKPD-0200 | B3: Essential Generator No1 | C3: Offline/Manual | D3: Quartely
A4: DNY_111-PKPD-0300 | B4: Essential Generator No2 | C4: Offline/Manual | D4: Quartely
A5: DNY_111-PKPD-0400 | B5: Essential Generator No3 | C5: Offline/Manual | D5: Quartely
A6: DNY_111-PKPG-0100 | B6: Main Power Generator A | C6: Online | D6: Monthly
A7: DNY_111-PKPG-0200 | B7: Main Power Generator B | C7: Online | D7: Monthly
A8: DNY_111-PKPG-0300 | B8: Main Power Generator C | C8: Online | D8: Monthly
A9: DNY_111-PKPG-0400 | B9: Main Power Generator D | C9: Online | D9: Monthly
A10: DNY_115-HVSF-9001-A | B10: FD Fan A | C10: Online | D10: Monthly
A11: DNY_115-HVSF-9001-B | B11: FD Fan B | C11: Online | D11: Monthly
A12: DNY_115-PUCE-9501-A | B12: Boiler Main Feed Water Pump A | C12: Online | D12: Monthly
... A340: UNY_775-PKGC-0200 | B340: Injection Gas Compressor B | C340: Online | D340: Monthly

Sheet Dropdowns
A1: Asset_Tag | B1: Status | C1: Method | D1: Period | E1: Measurement Type
A2: DNY_111-PKPD-0100 | B2: Acceptable | C2: Online | D2: Monthly | E2: OA
A3: DNY_111-PKPD-0200 | B3: Early Stage Fault | C3: Offline/Manual | D3: Quartely | E3: S1
A4: DNY_111-PKPD-0300 | B4: Progressed Fault | E4: VA
A5: DNY_111-PKPD-0400 | B5: Severe Fault | E5: OA+S1
A6: DNY_111-PKPG-0100 | B6: Unmeasured | E6: VA+OA
A7: DNY_111-PKPG-0200
A8: DNY_111-PKPG-0300
A9: DNY_111-PKPG-0400
A10: DNY_115-HVSF-9001-A
A11: DNY_115-HVSF-9001-B
A12: DNY_115-PUCE-9501-A
A13: DNY_115-PUCE-9501-B
A14: DNY_115-PUCE-9503-A
A15: DNY_115-PUCE-9503-B
A16: DNY_116-PUCE-0003-A
A17: DNY_116-PUCE-0003-B
A18: DNY_116-PURO-0003-A
... A340: UNY_775-PKGC-0200

Sheet Sheet3
C1: Survey Date
A2: 111-PKPD-5200 | B2: DNY | C2: 46133 | D2: comment B
A3: 111-PKPD-5200 | B3: DNY | C3: 46095 | D3: comment A
A4: 111-PKPD-5200 | B4: DNY | C4: 46057 | D4: fioafnasoinf
A5: 111-PKPD-5200 | B5: DNY | C5: 46019
A6: 111-PKPD-5200 | B6: DNY | C6: 45981
A7: 111-PKPD-5200 | B7: DNY | C7: 45943
